Workbook

Sheet fChamados
A1: ID Chamado | B1: ID Motivo | C1: ID Usuário | D1: ID Operador | E1: ID Status | F1: Data Abertura | G1: Data Encerrado
A2: 1 | B2: 31 | C2: 24 | D2: 1 | E2: 5 | F2: 42738.37 | G2: 42738.431
A3: 2 | B3: 10 | C3: 68 | D3: 6 | E3: 5 | F3: 42738.404 | G3: 42744.494
A4: 3 | B4: 27 | C4: 22 | D4: 3 | E4: 5 | F4: 42738.451 | G4: 42746.431
A5: 4 | B5: 7 | C5: 61 | D5: 5 | E5: 5 | F5: 42738.508 | G5: 42739.378
A6: 5 | B6: 11 | C6: 19 | D6: 6 | E6: 5 | F6: 42738.633 | G6: 42747.733
A7: 6 | B7: 27 | C7: 66 | D7: 3 | E7: 5 | F7: 42738.647 | G7: 42746.417
A8: 7 | B8: 6 | C8: 25 | D8: 5 | E8: 5 | F8: 42738.66 | G8: 42739.56
A9: 8 | B9: 28 | C9: 3 | D9: 1 | E9: 5 | F9: 42738.667 | G9: 42738.733
A10: 9 | B10: 35 | C10: 76 | D10: 1 | E10: 5 | F10: 42739.383 | G10: 42739.472
A11: 10 | B11: 15 | C11: 68 | D11: 4 | E11: 5 | F11: 42739.398 | G11: 42751.578
A12: 11 | B12: 35 | C12: 43 | D12: 1 | E12: 5 | F12: 42739.43 | G12: 42739.495
A13: 12 | B13: 9 | C13: 23 | D13: 6 | E13: 5 | F13: 42739.585 | G13: 42744.695
... A10132: 10131 | B10132: 40 | C10132: 36 | D10132: 3 | E10132: 5 | F10132: 44493.604 | G10132: 44494.524
A10133: 10132 | B10133: 17 | C10133: 34 | D10133: 6 | E10133: 4 | F10133: 44494.378
A10134: 10133 | B10134: 19 | C10134: 31 | D10134: 7 | E10134: 5 | F10134: 44494.479 | G10134: 44494.496
A10135: 10134 | B10135: 33 | C10135: 46 | D10135: 1 | E10135: 5 | F10135: 44494.621 | G10135: 44500.501
A10136: 10135 | B10136: 24 | C10136: 35 | D10136: 1 | E10136: 5 | F10136: 44494.622 | G10136: 44494.703
A10137: 10136 | B10137: 5 | C10137: 76 | D10137: 5 | E10137: 5 | F10137: 44494.63 | G10137: 44495.58
A10138: 10137 | B10138: 9 | C10138: 27 | D10138: 6 | E10138: 5 | F10138: 44494.689 | G10138: 44499.729
A10139: 10138 | B10139: 15 | C10139: 66 | D10139: 4 | E10139: 5 | F10139: 44494.73 | G10139: 44505.51
A10140: 10139 | B10140: 28 | C10140: 8 | D10140: 1 | E10140: 5 | F10140: 44495.343 | G10140: 44495.439
A10141: 10140 | B10141: 15 | C10141: 56 | D10141: 4 | E10141: 5 | F10141: 44495.35 | G10141: 44510.47
A10142: 10141 | B10142: 29 | C10142: 19 | D10142: 2 | E10142: 5 | F10142: 44495.521 | G10142: 44496.771
A10143: 10142 | B10143: 21 | C10143: 17 | D10143: 7 | E10143: 5 | F10143: 44495.564 | G10143: 44495.581
A10144: 10143 | B10144: 37 | C10144: 46 | D10144: 2 | E10144: 5 | F10144: 44495.572 | G10144: 44496.702
A10145: 10144 | B10145: 31 | C10145: 25 | D10145: 1 | E10145: 5 | F10145: 44495.588 | G10145: 44495.646
... A10254: 10253 | B10254: 32 | C10254: 2 | D10254: 1 | E10254: 5 | F10254: 44516.434 | G10254: 44517.484
A10255: 10254 | B10255: 17 | C10255: 53 | D10255: 6 | E10255: 2 | F10255: 44516.505
A10256: 10255 | B10256: 8 | C10256: 48 | D10256: 5 | E10256: 5 | F10256: 44516.547 | G10256: 44517.507
A10257: 10256 | B10257: 37 | C10257: 62 | D10257: 2 | E10257: 5 | F10257: 44517.414 | G10257: 44518.714
A10258: 10257 | B10258: 26 | C10258: 47 | D10258: 2 | E10258: 5 | F10258: 44517.457 | G10258: 44518.527
A10259: 10258 | B10259: 6 | C10259: 50 | D10259: 5 | E10259: 5 | F10259: 44517.55 | G10259: 44518.78
A10260: 10259 | B10260: 26 | C10260: 32 | D10260: 2 | E10260: 5 | F10260: 44517.604 | G10260: 44518.764
A10261: 10260 | B10261: 24 | C10261: 28 | D10261: 1 | E10261: 5 | F10261: 44517.684 | G10261: 44517.76
A10262: 10261 | B10262: 25 | C10262: 12 | D10262: 1 | E10262: 5 | F10262: 44518.414 | G10262: 44518.737
A10263: 10262 | B10263: 39 | C10263: 20 | D10263: 2 | E10263: 5 | F10263: 44518.454 | G10263: 44518.556
A10264: 10263 | B10264: 38 | C10264: 5 | D10264: 1 | E10264: 5 | F10264: 44518.53 | G10264: 44518.538
A10265: 10264 | B10265: 10 | C10265: 54 | D10265: 6 | E10265: 5 | F10265: 44518.573 | G10265: 44525.363
A10266: 10265 | B10266: 23 | C10266: 23 | D10266: 8 | E10266: 5 | F10266: 44518.59 | G10266: 44518.606
...

Sheet fChamados1
B1: =RANDBETWEEN(42736,44561) -> 43344 | C1: =RANDBETWEEN(333,750)/1000 -> 0.546 | D1: =RANDBETWEEN(1,41) -> 21 | E1: =RANDBETWEEN(1,76) -> 5 | F1: =VLOOKUP(D1,#REF!,6,0) -> #REF! | G1: =B1+C1+K1 -> #REF! | H1: =B1+C1 -> 43344.546 | I1: =((F1/60)/24) -> #REF! | J1: =RANDBETWEEN(70,130)/100 -> 1.26 | K1: =I1*J1 -> #REF! | L1: =G1-H1 -> #REF! | M1: =L1*60*24 -> #REF! | N1: =HOUR(G1) -> #REF!
A2: ID Chamado | B2: Data Abertura | C2: Hora Abertura | D2: ID Motivo | E2: ID Usuário | F2: SLA
B3: 42736 | C3: 0.401 | D3: 21 | E3: 31 | F3: 30 | G3: 42736.419 | H3: 42736.401 | I3: 0.020833333 | J3: 0.87 | K3: 0.018125 | L3: 0.018125 | M3: 26.1 | N3: 10
B4: 42736 | C4: 0.441 | D4: 23 | E4: 8 | F4: 30 | G4: 42736.46 | H4: 42736.441 | I4: 0.020833333 | J4: 0.93 | K4: 0.019375 | L4: 0.019375 | M4: 27.9 | N4: 11
B5: 42736 | C5: 0.457 | D5: 38 | E5: 29 | F5: 15 | G5: 42736.467 | H5: 42736.457 | I5: 0.010416667 | J5: 0.94 | K5: 0.0097916667 | L5: 0.0097916667 | M5: 14.1 | N5: 11
B6: 42736 | C6: 0.466 | D6: 28 | E6: 19 | F6: 120 | G6: 42736.571 | H6: 42736.466 | I6: 0.083333333 | J6: 1.26 | K6: 0.105 | L6: 0.105 | M6: 151.2 | N6: 13
B7: 42736 | C7: 0.563 | D7: 23 | E7: 20 | F7: 30 | G7: 42736.587 | H7: 42736.563 | I7: 0.020833333 | J7: 1.16 | K7: 0.024166667 | L7: 0.024166667 | M7: 34.8 | N7: 14
B8: 42736 | C8: 0.727 | D8: 13 | E8: 32 | F8: 60 | G8: 42736.773 | H8: 42736.727 | I8: 0.041666667 | J8: 1.1 | K8: 0.045833333 | L8: 0.045833333 | M8: 66 | N8: 18
B9: 42736 | C9: 0.686 | D9: 8 | E9: 2 | F9: 1440 | G9: 42737.416 | H9: 42736.686 | I9: 1 | J9: 0.73 | K9: 0.73 | L9: 0.73 | M9: 1051.2 | N9: 9
B10: 42737 | C10: 0.418 | D10: 21 | E10: 42 | F10: 30 | G10: 42737.438 | H10: 42737.418 | I10: 0.020833333 | J10: 0.95 | K10: 0.019791667 | L10: 0.019791667 | M10: 28.5 | N10: 10
B11: 42736 | C11: 0.614 | D11: 37 | E11: 20 | F11: 1440 | G11: 42737.484 | H11: 42736.614 | I11: 1 | J11: 0.87 | K11: 0.87 | L11: 0.87 | M11: 1252.8 | N11: 11
B12: 42736 | C12: 0.625 | D12: 8 | E12: 55 | F12: 1440 | G12: 42737.535 | H12: 42736.625 | I12: 1 | J12: 0.91 | K12: 0.91 | L12: 0.91 | M12: 1310.4 | N12: 12
B13: 42736 | C13: 0.355 | D13: 7 | E13: 59 | F13: 1440 | G13: 42737.655 | H13: 42736.355 | I13: 1 | J13: 1.3 | K13: 1.3 | L13: 1.3 | M13: 1872 | N13: 15
B14: 42738 | C14: 0.37 | D14: 31 | E14: 24 | F14: 120 | G14: 42738.431 | H14: 42738.37 | I14: 0.083333333 | J14: 0.73 | K14: 0.060833333 | L14: 0.060833333 | M14: 87.6 | N14: 10
... B10689: 44539 | C10689: 0.34 | D10689: 17 | E10689: 76 | F10689: 86400 | G10689: 44615.54 | H10689: 44539.34 | I10689: 60 | J10689: 1.27 | K10689: 76.2 | L10689: 76.2 | M10689: 109728 | N10689: 12

Sheet dUsuários
A1: ID Usuário | B1: Nome Usuário | C1: Login | D1: Email | E1: ID Departamento
A2: 1 | B2: Agatha Viana | C2: agatha.viana | D2: agatha.viana@empresa.com | E2: 8
A3: 2 | B3: Alice Castro | C3: alice.castro | D3: alice.castro@empresa.com | E3: 11
A4: 3 | B4: Ana Beatriz Lima | C4: ana.lima | D4: ana.lima@empresa.com | E4: 6
A5: 4 | B5: Ana Carolina Carvalho | C5: ana.carvalho | D5: ana.carvalho@empresa.com | E5: 11
A6: 5 | B6: Ana Julia da Paz | C6: ana.paz | D6: ana.paz@empresa.com | E6: 1
A7: 6 | B7: Ana Vitória Fernandes | C7: ana.fernandes | D7: ana.fernandes@empresa.com | E7: 5
A8: 7 | B8: Ana Vitória Santos | C8: ana.santos | D8: ana.santos@empresa.com | E8: 1
A9: 8 | B9: Arthur das Neves | C9: arthur.neves | D9: arthur.neves@empresa.com | E9: 10
A10: 9 | B10: Augusto Viana | C10: augusto.viana | D10: augusto.viana@empresa.com | E10: 3
A11: 10 | B11: Bruna Alves | C11: bruna.alves | D11: bruna.alves@empresa.com | E11: 8
A12: 11 | B12: Calebe Azevedo | C12: calebe.azevedo | D12: calebe.azevedo@empresa.com | E12: 5
A13: 12 | B13: Caroline Oliveira | C13: caroline.oliveira | D13: caroline.oliveira@empresa.com | E13: 10
... A77: 76 | B77: Yasmin Fernandes | C77: yasmin.fernandes | D77: yasmin.fernandes@empresa.com | E77: 3

Sheet dOperadores
A1: ID Operador | B1: Nome | C1: Login | D1: Email | E1: Equipe | F1: Nível
A2: 1 | B2: Carlos Eduardo Souza | C2: carlos.souza | D2: carlos.souza@empresa.com | E2: Infraestrutura | F2: Nível 1
A3: 2 | B3: Davi Moraes | C3: davi.moraes | D3: davi.moraes@empresa.com | E3: Infraestrutura | F3: Nível 2
A4: 3 | B4: Vitor Viana | C4: vitor.viana | D4: vitor.viana@empresa.com | E4: Infraestrutura | F4: Nível 3
A5: 4 | B5: Bruno Araújo | C5: bruno.araujo | D5: bruno.araujo@empresa.com | E5: Sistemas | F5: Nível 1
A6: 5 | B6: Camila Ribeiro | C6: camila.ribeiro | D6: camila.ribeiro@empresa.com | E6: Sistemas | F6: Nível 2
A7: 6 | B7: Alana Martins | C7: alana.martins | D7: alana.martins@empresa.com | E7: Sistemas | F7: Nível 3
A8: 7 | B8: Beatriz Moura | C8: beatriz.moura | D8: beatriz.moura@empresa.com | E8: Suporte | F8: Nível 1
A9: 8 | B9: Pietro Costa | C9: pietro.costa | D9: pietro.costa@empresa.com | E9: Suporte | F9: Nível 1

Sheet dMotivos
A1: ID Motivos | B1: Motivos | C1: Nível | D1: Equipe | E1: ID SLA
A2: =IFERROR(A1+1,1) -> 1 | B2: Erros ERP | C2: Nível 1 | D2: Sistemas | E2: 8
A3: =IFERROR(A2+1,1) -> 2 | B3: Erros Windows | C3: Nível 1 | D3: Sistemas | E3: 8
A4: =IFERROR(A3+1,1) -> 3 | B4: Erros Linux | C4: Nível 1 | D4: Sistemas | E4: 8
A5: =IFERROR(A4+1,1) -> 4 | B5: Erros Email | C5: Nível 1 | D5: Sistemas | E5: 8
A6: =IFERROR(A5+1,1) -> 5 | B6: Erros ERP | C6: Nível 2 | D6: Sistemas | E6: 10
A7: =IFERROR(A6+1,1) -> 6 | B7: Erros Windows | C7: Nível 2 | D7: Sistemas | E7: 10
A8: =IFERROR(A7+1,1) -> 7 | B8: Erros Linux | C8: Nível 2 | D8: Sistemas | E8: 10
A9: =IFERROR(A8+1,1) -> 8 | B9: Erros Email | C9: Nível 2 | D9: Sistemas | E9: 10
A10: =IFERROR(A9+1,1) -> 9 | B10: Erros ERP | C10: Nível 3 | D10: Sistemas | E10: 14
A11: =IFERROR(A10+1,1) -> 10 | B11: Erros Windows | C11: Nível 3 | D11: Sistemas | E11: 14
A12: =IFERROR(A11+1,1) -> 11 | B12: Erros Linux | C12: Nível 3 | D12: Sistemas | E12: 14
A13: =IFERROR(A12+1,1) -> 12 | B13: Erros Email | C13: Nível 3 | D13: Sistemas | E13: 14
... A42: =IFERROR(A41+1,1) -> 41 | B42: Solicitar treinamento sistema | C42: Nível 2 | D42: Sistemas | E42: 15

Sheet dStatus
A1: ID Status | B1: Status
A2: 1 | B2: Aguardando atendimento
A3: 2 | B3: Em atendimento
A4: 3 | B4: Em estudo
A5: 4 | B5: Em fila de desenvolvimento
A6: 5 | B6: Encerrada
A7: 6 | B7: Aguardando aprovação
A8: 7 | B8: Aguardando retorno usuário
A9: 8 | B9: Aguardando retorno fornecedor

Sheet dSLA
A1: ID SLA | B1: SLA Tempo (min) | C1: SLA Descricao
A2: 1 | B2: 15 | C2: 15 minutos
A3: 2 | B3: 30 | C3: 30 minutos
A4: 3 | B4: 45 | C4: 45 minutos
A5: 4 | B5: 60 | C5: 1 hora
A6: 5 | B6: 120 | C6: 2 horas
A7: 6 | B7: 180 | C7: 3 horas
A8: 7 | B8: 240 | C8: 4 horas
A9: 8 | B9: 480 | C9: 8 horas
A10: 9 | B10: 720 | C10: 12 horas
A11: 10 | B11: 1440 | C11: 24 horas
A12: 11 | B12: 1080 | C12: 2 dias
A13: 12 | B13: 4320 | C13: 3 dias
... A24: 23 | B24: 86400 | C24: 2 meses

Sheet dDepartamentos
A1: ID Departamento | B1: Departamento | C1: Qtd Funcionários
A2: 1 | B2: Recursos Humanos | C2: =COUNTIF(dUsuários!E:E,Tabela5[[#This Row],[ID Departamento]]) -> 6
A3: 2 | B3: Jurídico | C3: =COUNTIF(dUsuários!E:E,Tabela5[[#This Row],[ID Departamento]]) -> 4
A4: 3 | B4: Financeiro | C4: =COUNTIF(dUsuários!E:E,Tabela5[[#This Row],[ID Departamento]]) -> 5
A5: 4 | B5: Compras | C5: =COUNTIF(dUsuários!E:E,Tabela5[[#This Row],[ID Departamento]]) -> 5
A6: 5 | B6: Fiscal | C6: =COUNTIF(dUsuários!E:E,Tabela5[[#This Row],[ID Departamento]]) -> 5
A7: 6 | B7: Comercial | C7: =COUNTIF(dUsuários!E:E,Tabela5[[#This Row],[ID Departamento]]) -> 8
A8: 7 | B8: Marketing | C8: =COUNTIF(dUsuários!E:E,Tabela5[[#This Row],[ID Departamento]]) -> 4
A9: 8 | B9: Logística | C9: =COUNTIF(dUsuários!E:E,Tabela5[[#This Row],[ID Departamento]]) -> 13
A10: 9 | B10: Engenharia | C10: =COUNTIF(dUsuários!E:E,Tabela5[[#This Row],[ID Departamento]]) -> 5
A11: 10 | B11: Qualidade | C11: =COUNTIF(dUsuários!E:E,Tabela5[[#This Row],[ID Departamento]]) -> 5
A12: 11 | B12: Operacional | C12: =COUNTIF(dUsuários!E:E,Tabela5[[#This Row],[ID Departamento]]) -> 16
